Workbook

Sheet Guidance Sheet
B1: Guide to Completing a Test Script
B3: 1. File Naming:
B4: The file should be named using the version format provided in the sample (e.g., Product Name Test Script v0.1).
B6: 2. Test Date:
B7: Always include the date when the test is conducted.
B9: 3. Approval for Live Environment:
B10: The test script can only be approved if it pertains to the live environment.
B12: 4. Sign-off Requirement:
B13: The approver must sign off on the test script before it is moved to the live environment.
B15: 5. Environment Specification:
B16: Indicate the environment where the test was conducted (e.g., Development, Staging, or Live).
B18: 6. Document Category:
... B28: Ensure that the use case numbers of the tested scenarios are clearly indicated.

Sheet ECMS Test Script
D3: Gov Conference Test Script
D8: Date : | F8: Tester Name & Sign:
F9: Version:
F10: Environment: | G10: Staging
D11: Number of Passed Test Scenarios: | E11: ='LOGIN TO ECMS'!E11+#REF!+DASHBOARD!E9+REQUEST!E10+#REF!+TICKET!E10+'WORKFLOW '!E11+#REF! -> #REF! | F11: Doc Category: | G11: External
D12: Number of Failed Test Scenarios: | E12: ='LOGIN TO ECMS'!E12+#REF!+DASHBOARD!E10+REQUEST!E11+#REF!+TICKET!E11+'WORKFLOW '!E12+#REF! -> #REF! | F12: % of Passed Test Scenarios: | G12: =E11/E13*100 -> #REF!
D13: Total Number of Test Scenarios: | E13: =SUM(E11:E12) -> #REF! | F13: % of Failed Test Scenarios: | G13: =E12/E13*100 -> #REF!
D16: Document Control Log:
D17: Version | E17: Use Case No | F17: Feature Added
A27: S/No | B27: Features | D27: Steps to Reproduce | E27: Expected results | F27: Pass/Fail | G27: Comments and Observations
D29: Login
D30: Enter url: https://www.1gov.ng/ | E30: takes you to the 1gov login page | F30: ='LOGIN TO ECMS'!F19 -> Pass
D31: Click Login | E31: Open page where the MDA can enter their login detail:Domain Name, Email field, Password filed, Login buttion field | F31: ='LOGIN TO ECMS'!F20 -> Pass
D32: End Test | F32: ='LOGIN TO ECMS'!F21
F33: ='LOGIN TO ECMS'!F22
D34: Login (with correct details) | F34: ='LOGIN TO ECMS'!F23
D35: Click on Login | E35: Displays Login page | F35: ='LOGIN TO ECMS'!F24 -> Pass
D36: Enter Your Domain | E36: Display Domain name | F36: ='LOGIN TO ECMS'!F25 -> Pass
D37: Enter Email | E37: Display Email | F37: ='LOGIN TO ECMS'!F26 -> Pass
D38: Enter Password | E38: Display and hide Password | F38: ='LOGIN TO ECMS'!F27 -> Pass
D39: Click Login | E39: opens the Home Page of the MDA | F39: ='LOGIN TO ECMS'!F28 -> Pass
D40: End Test | F40: ='LOGIN TO ECMS'!F29
D42: Login (with wrong Domain)
D43: Click on Login | E43: Displays Login page | F43: ='LOGIN TO ECMS'!F32 -> Pass
D44: Enter Your Domain | E44: Display Domain name
D45: Enter Email | E45: Display Email
A46: 1 | D46: Enter Password | E46: Display and hide Password
B47: LOGIN WITHOUT 2FA | D47: Click Login | E47: Display 'Invalid Email or Password'
D48: End Test
D50: Login (with wrong email)
D51: Click on Login | E51: Displays Login page
D52: Enter Your Domain | E52: Display Domain name
D53: Enter Email | E53: Display Email
D54: Enter Password | E54: Display and hide Password
D55: Click Login | E55: Display 'Invalid Email or Password'
D56: End Test
D58: Login (with wrong password)
D59: Click on Login | E59: Displays Login page
D60: Enter Your Domain | E60: Display Domain name
D61: Enter Email | E61: Display Email
...

Sheet TOTAL TEST RESULT
D17: ECMS Test Script
D19: Date : | F19: Tester Name & Sign:
F20: Version:
F21: Environment: | G21: Pre Production
D22: Total Number of Passed Test Scenarios: | E22: ='LOGIN TO ECMS'!E11 +DASHBOARD!E9 +REQUEST!E10 +TICKET!E10 +'WORKFLOW '!E11 -> #REF! | F22: Doc Category: | G22: Internal
D23: Total Number of Failed Test Scenarios: | E23: ='LOGIN TO ECMS'!E12 +DASHBOARD!E10 +REQUEST!E11 +TICKET!E11 +'WORKFLOW '!E12 -> #REF! | F23: % of Passed Test Scenarios: | G23: =(E22/E24)*100 -> #REF!
D24: Total Number of Test Scenarios: | E24: =E22+E23 -> #REF! | F24: % of Failed Test Scenarios: | G24: =(E23/E24)*100 -> #REF!

Sheet DASHBOARD
I2: Pass
I3: Fail
D4: ECMS Test Script
D6: Date : | F6: Tester Name & Sign:
F7: Version:
F8: Environment: | G8: Pre Production
D9: Number of Passed Test Scenarios: | E9: =COUNTIF(F15:F34,I2) -> 17 | F9: Doc Category: | G9: Internal
D10: Number of Failed Test Scenarios: | E10: =COUNTIF(F15:F34,I3) -> 0 | F10: % of Passed Test Scenarios: | G10: =(E9/E11)*100 -> 100
D11: Number of Test Scenarios: | E11: =SUM(E9:E10) -> 17 | F11: % of Failed Test Scenarios: | G11: =(E10/E11)*100 -> 0
B14: Features | D14: Steps to Reproduce | E14: Expected results | F14: Pass/Fail | G14: Comments and Observations
B15: DASHBOARD | D15: Workflow Dashboard
D16: From the left menu, click Dashboard | E16: Dashboard Page Expands | F16: Pass
D17: Click Workflow Dashboard | E17: Workflow Dashboard loads successfully | F17: Pass
D18: Hover over the green “New Ticket” tab under Ticket Status | E18: Tooltip appears showing: “This refers to new tickets created on a particular day.” | F18: Pass
D19: Click Today filter | E19: Ticket Status updates to show today’s ticket statistics | F19: Pass
D20: Click Week filter | E20: Ticket Status updates to show ticket statistics for the current week | F20: Pass
D21: Click Month filter | E21: Ticket Status updates to show statistics for the current month | F21: Pass
D22: Select a custom date range from the date filter | E22: Ticket Status updates based on the selected date range | F22: Pass
D23: Verify that Open, In Progress, and Closed ticket counts update correctly | E23: Values update dynamically according to applied filters | F23: Pass
D24: Scroll to Workflow Ticket Summary (Bar Chart) | E24: Chart loads correctly with bars for each workflow | F24: Pass
D25: Hover over a bar in the chart | E25: Tooltip displays workflow name + count of Open / In Progress / Closed tickets | F25: Pass
D26: Click Open status Badge (legend)** | E26: only Inprogress and closed bars are displayed | F26: Pass
D27: Click In progress Badge | E27: only closed bars are displayed | F27: Pass
... D32: Hover over the bar for the selected queue | E32: Tooltip shows correct workflow summary for that queue | F32: Pass
D33: End Test

Sheet LOGIN TO ECMS
I2: Pass
I3: Fail
D6: ECMS Test Script
D8: Date : | F8: Tester Name & Sign:
F9: Version:
F10: Environment: | G10: Pre Production
D11: Number of Passed Test Scenarios: | E11: =COUNTIF(F18:F71,I2) -> 30 | F11: Doc Category: | G11: Internal
D12: Number of Failed Test Scenarios: | E12: =COUNTIF(F19:F71,I3) -> 0 | F12: % of Passed Test Scenarios: | G12: =(E11/E13)*100 -> 100
D13: Number of Test Scenarios: | E13: =SUM(E11:E12) -> 30 | F13: % of Failed Test Scenarios: | G13: =(E12/E13)*100 -> 0
B16: Features | D16: Steps to Reproduce | E16: Expected results | F16: Pass/Fail | G16: Comments and Observations
D18: Login
D19: Enter url: https://www.1gov.ng/ | E19: takes you to the 1gov login page | F19: Pass
D20: Click Login | E20: Open page where the MDA can enter their login detail:Domain Name, Email field, Password filed, Login buttion field | F20: Pass
D21: End Test
D23: Login (with correct details)
D24: Click on Login | E24: Displays Login page | F24: Pass
D25: Enter Your Domain | E25: Display Domain name | F25: Pass
D26: Enter Email | E26: Display Email | F26: Pass
D27: Enter Password | E27: Display and hide Password | F27: Pass
D28: Click Login | E28: opens the Home Page of the MDA | F28: Pass
D29: End Test
D31: Login (with wrong Domain)
D32: Click on Login | E32: Displays Login page | F32: Pass
D33: Enter Your Domain | E33: Display Domain name | F33: Pass
D34: Enter Email | E34: Display Email | F34: Pass
D35: Enter Password | E35: Display and hide Password | F35: Pass
B36: LOGIN | D36: Click Login | E36: Display 'Invalid Email or Password' | F36: Pass
D37: End Test
D39: Login (with wrong email)
D40: Click on Login | E40: Displays Login page | F40: Pass
D41: Enter Your Domain | E41: Display Domain name | F41: Pass
D42: Enter Email | E42: Display Email | F42: Pass
D43: Enter Password | E43: Display and hide Password | F43: Pass
D44: Click Login | E44: Display 'Invalid Email or Password' | F44: Pass
D45: End Test
D47: Login (with wrong password)
D48: Click on Login | E48: Displays Login page | F48: Pass
D49: Enter Your Domain | E49: Display Domain name | F49: Pass
D50: Enter Email | E50: Display Email | F50: Pass
D51: Enter Password | E51: Display and hide Password | F51: Pass
...

Sheet REQUEST
I2: Pass
I3: Fail
D5: ECMS Test Script
D7: Date : | F7: Tester Name & Sign:
F8: Version:
F9: Environment: | G9: Pre Production
D10: Number of Passed Test Scenarios: | E10: =COUNTIF(F16:F43,I2) -> 24 | F10: Doc Category: | G10: Internal
D11: Number of Failed Test Scenarios: | E11: =COUNTIF(F16:F43,I3) -> 0 | F11: % of Passed Test Scenarios: | G11: =(E10/E12)*100 -> 100
D12: Number of Test Scenarios: | E12: =SUM(E10:E11) -> 24 | F12: % of Failed Test Scenarios: | G12: =(E11/E12)*100 -> 0
B14: Features | D14: Steps to Reproduce | E14: Expected results | F14: Pass/Fail | G14: Comments and Observations
B16: REQUEST | D16: Internal Request
D17: Click on Request | E17: The App should display; 1. Internal request tab 2. External request tab | F17: Pass
D18: Click internal | E18: Should display the queue category and all currently active internal forms within each category, excluding any forms that are suspended. | F18: Pass
D19: Click on form name | E19: Should display these options; 1. View Form 2. Share form | F19: Pass
D20: Click View form | E20: Should display form | F20: Pass
D21: Enter details in form | E21: Should display data entered | F21: Pass
D22: Click Submit | E22: Should submit form and display success message with reference number | F22: Pass
D23: For share option, Click Share | E23: Should display share mediums i.e facebook,whatsapp, twitter and the unique form link | F23: Pass
D24: Copy link | E24: Should allow user copy form link | F24: Pass
D25: Paste link on a web portal | E25: Should allow user paste link on a web portal | F25: Pass
D26: clcik form link | E26: should open form in ECMS app | F26: Pass
D27: End Test | F27: Pass
F28: Pass
D29: External Request | F29: Pass
D30: Click on Request | E30: The App should display; 1. Internal request tab 2. External request tab | F30: Pass
D31: Click external | E31: Should display the queue category and all currently active external forms within each category, excluding any forms that are suspended. | F31: Pass
D32: Click on form name | E32: Should display these options; 1. View Form 2. Share form | F32: Pass
D33: Click View form | E33: Should display form | F33: Pass
D34: Enter details in form | E34: Should display data entered | F34: Pass
D35: Click Submit | E35: Should submit form and display success message with reference number | F35: Pass
D36: For share option, Click Share | E36: Should display share mediums i.e facebook,whatsapp, twitter and the unique form link | F36: Pass
D37: Copy link | E37: Should allow user copy form link | F37: Pass
D38: Paste link on a web portal | E38: Should allow user paste link on a web portal | F38: Pass
D39: Click form link | E39: Should open form in ECMS app | F39: Pass
D40: End Test | F40: Pass

Sheet TICKET
J2: Pass
J3: Fail
D5: ECMS Test Script
D7: Date : | F7: Tester Name & Sign:
F8: Version:
F9: Environment: | G9: Pre Produdciton
D10: Number of Passed Test Scenarios: | E10: =COUNTIF(F38:F212,J2) -> 0 | F10: Doc Category: | G10: Internal
D11: Number of Failed Test Scenarios: | E11: =COUNTIF(F38:F212,J3) -> 0 | F11: % of Passed Test Scenarios: | G11: =(E10/E12)*100 -> #DIV/0!
D12: Number of Test Scenarios: | E12: =SUM(E10:E11) -> 0 | F12: % of Failed Test Scenarios: | G12: =(E11/E12)*100 -> #DIV/0!
B16: Features | D16: Steps to Reproduce | E16: Expected results | F16: Pass/Fail | G16: Comments and Observations
B18: CREATE TICKET | D18: Create Ticket
D19: From the left menu, click on tickets | E19: Tickets submenu expands showing: Create Ticket, View All Tickets, View Ticket Approvals | F19: Pass
D20: Click Create Ticket | E20: Create Ticket screen loads with dropdowns for Queue and Queue Type | F20: Pass
D21: Click on Queue dropdown | E21: System displays all available queues the user has access to | F21: Pass
D22: Select a valid Queue | E22: Queue Type dropdown is activated (if not already active) | F22: Pass
D23: Click on Queue Type dropdown | E23: System displays queue types mapped to the selected queue | F23: Pass
D24: Select a valid Queue Type | E24: System auto-loads the dynamic ticket creation form based on workflow configuration for that Queue + Queue Type | F24: Pass
D25: Verify that required UI fields appear (e.g. Customer name, Email, Address fields, Priority, Attach File etc.) | E25: All form fields configured in workflow appear correctly with labels, validations, and proper alignment | F25: Pass
D26: Begin filling in the form with valid test data | E26: All fields accept valid inputs | F26: Pass
D27: Toggle “Assign this ticket right away?” to ON | E27: Assign to User dropdown becomes active | F27: Pass
D28: Click Assign to User dropdown | E28: Only users with: View Access + Workflow Access + Status Access appear in the dropdown | F28: Pass
D29: Select a vlaid user from the list | E29: User is assigned successfully | F29: Pass
D30: Review form and click Create | E30: System validates all required fields | F30: Pass
... D34: Open the ticket from the list | E34: Ticket opens correctly showing all entered data, attachments, priority, and assigned users | F34: Pass
D35: End Test
B38: VIEW TICKET | D38: View All Ticket
D39: Click Tickets on the left menu | E39: Ticket Submenu expands | F39: Pass
D40: Click View All Tickets | E40: User is redirected to the All Tickets page | F40: Pass
D41: Verify tabs: Assigned To Me, Assigned By Me, Created By Me, All Tickets, Inactive Tickets | E41: All tabs display correctly | F41: Pass
D42: Toggle the My Workflow / All Tickets switch | E42: Table updates according to selected filter | F42: Pass
D43: Click Search By dropdown | E43: Dropdown expands showing options: Ticket ID, Title, Contact Name, Company Name | F43: Pass
D44: Select Ticket ID from Search By | E44: Search input field becomes active for Ticket ID search | F44: Pass
D45: Type a valid Ticket ID in the Search input | E45: Matching ticket appears | F45: Pass
D46: Select Title from Search By | E46: Search input resets and is set to Title search | F46: Pass
D47: Type a keyword in Search input | E47: List displays tickets that contain the keyword in their title | F47: Pass
D48: Select Contact Name from Search By | E48: Search Input changes to accept accept contact name queries | F48: Pass
D49: Enter a valid contact name | E49: Tickets linked to that contact appear | F49: Pass
D50: Select Company Name from Search By | E50: Search input now accepts organization name | F50: Pass
... D71: Click on save | E71: displays 'Access code changed Successfully!' | F71: Pass
D72: End Test
...

Sheet MEMO
J2: Pass
J3: Fail
D5: MEMO
D7: Date : | F7: Tester Name & Sign: | G7: Chinwuba Okafor
F8: Version:
F9: Environment: | G9: Staging
D10: Number of Passed Test Scenarios: | E10: {=E28(F19:F23,J2)} -> #NAME? | F10: Doc Category: | G10: Internal
D11: Number of Failed Test Scenarios: | E11: =COUNTIF(F19:F25,J3) -> 0 | F11: % of Passed Test Scenarios: | G11: =(E10/E13)*K16 -> #NAME?
D12: Number of Test Scenarios: | E12: =SUM(E10:E11) -> #NAME? | F12: % of Failed Test Scenarios: | G12: =(E11/E12)*100 -> #NAME?
B16: Features | D16: Steps to Reproduce | E16: Expected results | F16: Pass/Fail | G16: Comments and Observations
B18: MEMO
B19: CREATE MEMO | D19: Navigate to and click on the “Memo” dropdown. | E19: The Memo dropdown expands and displays a list of features including Create Memo, View All Memo, Memo Draft, and Memo Draft Preview. | F19: Pass
D20: Click on “Create Memo” to access the memo | E20: An easy-to-follow guide for the memo editor is displayed, helping the user understand how to create and format a memo. | F20: Pass
D21: Review the memo editor guide carefully and select the “Don’t show this guide again” checkbox. | E21: The user successfully understands the memo guide, and upon selecting the checkbox, the guide will not be displayed in future memo creation sessions. | F21: Pass
D22: Navigate to and click on the Create Memo | E22: The Create Memo page is displayed with editing tools available on top. A blank memo template appears below with the title “1Government Cloud Support”, showing the user’s address and the current date. | F22: Pass
D23: click on "sans seff module" | E23: A list of text style options—Sans Seff, Serif, and Monospace—is displayed, allowing the user to change the memo text style. | F23: Pass
D24: Click on "Styles menu" | E24: Display list of text of size, select a preferred text size. | F24: Pass
D25: Click on "Bold module" | E25: A list of text sizes is displayed, allowing the user to select their preferred text size for the memo. | F25: Pass
D26: Click on "Italic Module" | E26: The highlighted text is displayed in a slanted (italic) style. | F26: Pass
D27: Click on "Underline module" | E27: The highlighted text is displayed with an underline. | F27: Pass
D28: Click on "strikethrough module" | E28: The highlighted text is displayed with a line through it. | F28: Pass
D29: Click on the “A” icon to change the text color. | E29: The highlighted text color can be updated as per the user’s selection. | F29: Pass
D30: Click on the “A” icon to change the text background color. | E30: The background color of the highlighted text is updated according to the user’s selection. | F30: Pass
D31: Click on the “Alignment” module to view text alignment options. | E31: A list of alignment options—Left Align, Center Align, and Justify—is displayed, allowing the user to select their preferred text alignment. | F31: Pass
... D39: Highlight a text and click on the “Insert Formula” module. | E39: A dialog appears for entering a formula. After entering the formula and clicking Save, the highlighted text displays the inserted formula. | F39: Pass
D40: Click on the “Clear Formatting” module. | E40: All formatting (e.g., bold, italic, underline, color, alignment) applied to the selected text is removed, returning it to the default style.
D42: Navigate to and click on “Save Draft” | E42: A dialog appears asking if the user wants to save the memo as a draft. After entering a preferred file name and clicking Yes, the memo is saved in draft form, the user is directed to the memo draft page | F42: Pass
D43: Navigate to and click on “Save Memo” | E43: The memo is saved successfully, and a confirmation message is displayed indicating that the memo has been saved, then user is directed to the view all memo page. | F43: Fail | G43: Download the memo file,but a pop-up appears indicating “Failed to create memo."
D44: End Test
B46: VIEW ALL MEMO | D46: Navigate to and click on the “Memo” dropdown. | E46: The Memo dropdown expands and displays a list of features including Create Memo, View All Memo, Memo Draft, and Memo Draft Preview. | F46: Pass
D47: Click on “View All Memo”. | E47: A page is displayed showing a list of all saved memos, including their titles, dates, and status. | F47: Pass
D48: Select a memo and click on the "action" module | E48: Options for View, Update and attach to ticket are displayed, allowing the user to either view the memo details,update and attach to ticket | F48: Pass | G48: it is attach to ticket instead, of attach to task
D49: Click on the “View” module. | E49: The selected memo is opened in a read-only mode, allowing the user to review its content without making changes. | F49: Pass
D50: Navigate to and click on the “Update” module. | E50: he selected memo is opened in edit mode, allowing the user to modify its content and save the changes. | F50: Pass
D51: Observe the toolbar for the newly added “Add Reviewer” and “view feedbacks” modules. | E51: The toolbar displays two new features—Add Reviewer and Add Comment—allowing the user to assign reviewers and add comments to the memo. | F51: Pass
D52: Click on “Attach to Ticket” to initiate task creation. | E52: A new page is displayed showing the Create Task interface, allowing the user to attach the memo to a ticket. | F52: Pass
D53: Select a queue and its corresponding queue type from the available options. | E53: The selected queue and queue type are successfully applied. | F53: Pass
D54: Click on the "Create Module" button | E54: the module creation page/form is displayed | F54: Pass
D55: Entry the "Task Title" | E55: The task title is accepted and displayed in the input field. | F55: Pass
D56: Click on the “Attach Memo” link to upload a memo file to the task. | E56: A file selection dialog appears, allowing the user to choose a memo file. | F56: Pass
...

Sheet WORKFLOW  
J2: Pass
J3: Fail
D6: ECMS Test Script
D8: Date : | F8: Tester Name & Sign:
F9: Version:
F10: Environment: | G10: Pre Prodcution
D11: Number of Passed Test Scenarios: | E11: =COUNTIF(#REF!,J2) -> #REF! | F11: Doc Category: | G11: Internal
D12: Number of Failed Test Scenarios: | E12: =COUNTIF(#REF!,J3) -> #REF! | F12: % of Passed Test Scenarios: | G12: =(E11/E13)*100 -> #REF!
D13: Number of Test Scenarios: | E13: =SUM(E11:E12) -> #REF! | F13: % of Failed Test Scenarios: | G13: =(E12/E13)*100 -> #REF!
B15: Features | D15: Steps to Reproduce | E15: Expected results | F15: Pass/Fail | G15: Comments and Observations
B18: WORKFLOW | D18: Create Workflow
D19: From the Menu click on Workflow | E19: The system should display sub-menus; 1. Create workflow 2. My workflow | F19: Pass
D20: Click on Create workflow sub -menu | E20: Should display Create workflow page with 4 tabs 1. Process 2. Forms 3. Escalations 4. Approvals | F20: Pass
D21: On the process tab, click "Select Queue" | E21: Should display already created Queues for selection | F21: Pass
D22: To Create New Queue | F22: Pass
D23: Click on Create Queue | E23: Should display a modal for queue name and description input | F23: Pass
D24: Enter Queue name and description and click on save and select | E24: Should successfully creates and select queue on process tab | F24: Pass
D25: To Create Queue Type | F25: Pass
D26: Click on create New queue type | E26: Should display a modal for queue type name and description input | F26: Pass
D27: Enter Queue type name and description and click on save and select | E27: Should successfully create and select queue type on process form | F27: Pass
D28: To Add Status | F28: Pass
D29: Click Select Status | E29: Should display Status (Open) and Closed as default and allows user search and select status | F29: Pass
D30: To Create New Status | F30: Pass
D31: Click Create Status | E31: Should display Create new status modal page | F31: Pass
D32: Enter name, and Description and click on save and select | E32: Should successfully create status and select status on the process form | F32: Pass
D33: Click Next button | E33: Should display Form page | F33: Pass
D34: To Customize Form for workflow | F34: Pass
D35: View the following on the form page 1. Fields 2. Default fields (Title and Description) 3. Help Guide | E35: System should display the following on the form page 1. Fields 2. Default fields (Title and Description) 3. Help Guide | F35: Pass
D36: Hide the title and the description by selecting the checkbox (if necessary) | E36: The title and description should be checked and hidden from the form (during ticket creation) | F36: Pass
D37: Drag and Drop form field | E37: Form field selected should be displayed on form panel | F37: Pass
D38: Click on next button | E38: Should Display the escalation page | F38: Pass
D39: To Add Escalation To Workflow | F39: Pass
D40: Click Add escalation on status button link | E40: Should display escalation modal having add button | F40: Pass
D41: Select who the escalation would be sent to by selecting the escalation type from the drop-down such as line manager, and role | E41: Should display the escalation type that is selected | F41: Pass
D42: Select Line manager escalation type | E42: Should display Line manager and time value box | F42: Pass
D43: Enter Time value | E43: Should display time value | F43: Pass
D44: Click on save button | E44: The escalation record should be saved | F44: Pass
D45: If the escalation type is "Role," choose just the role or choose role and department (directly aligning the role with the specific department). | E45: Should display just role, or role and department(if department was selected) | F45: Pass
D46: Enter Time value | E46: Should display time value | F46: Pass
D47: Click on save button | E47: The escalation record should be saved | F47: Pass
...

Sheet FORMS
I2: Pass
I3: Fail
D6: ECMS Test Script
D8: Date : 13th April 2026 | F8: Tester Name & Sign:
F9: Version:
F10: Environment: | G10: Pre Production
D11: Number of Passed Test Scenarios: | E11: =COUNTIF(F18:F258,I2) -> 239 | F11: Doc Category: | G11: Internal
D12: Number of Failed Test Scenarios: | E12: =COUNTIF(F19:F258,I3) -> 0 | F12: % of Passed Test Scenarios: | G12: =(E11/E13)*100 -> 100
D13: Number of Test Scenarios: | E13: =SUM(E11:E12) -> 239 | F13: % of Failed Test Scenarios: | G13: =(E12/E13)*100 -> 0
B16: Features | D16: Steps to Reproduce | E16: Expected results | F16: Pass/Fail | G16: Comments and Observations
B18: FORMS | D18: Create a Form
D19: From the Menu click on Form | E19: A sub menu create form button and all form is displayed | F19: Pass
D20: Click on Create form sub -menu | E20: Should display Create form page | F20: Pass
D21: End test | F21: Pass
F22: Pass
D23: Internal Form | F23: Pass
D24: Enter name of form | E24: Should display name of the form | F24: Pass
D25: Upload a fille | E25: File should be uploaded and displayed | F25: Pass
D26: Enter description | E26: Description should be displayed | F26: Pass
D27: Select a form type (Internal) | E27: Form type radio button should be selected | F27: Pass
D28: Click on Create button | E28: Should display a successful message, "form created successfully.' | F28: Pass
D29: Drag & drop form field | E29: Should display form field in the form page | F29: Pass
D30: Click and Select Queue | E30: Should display Queue | F30: Pass
D31: Click and Select Queue Type | E31: Should display Queue Type | F31: Pass
D32: End test | F32: Pass
F33: Pass
D34: Form Setting | F34: Pass
D35: Enable form setting | E35: Should display the start date and end date fields | F35: Pass
D36: Enable form type (Internal) | E36: Form type should be enabled to internal | F36: Pass
D37: Enter Initial email reponse message | E37: Should display email response message | F37: Pass
D38: Click on Save | E38: Should display Created successfully. | F38: Pass
D39: End test | F39: Pass
F40: Pass
F41: Pass
D42: External Form | F42: Pass
D43: Enter name of form | E43: Should display name of the form | F43: Pass
D44: Upload a fille | E44: File should be uploaded and displayed | F44: Pass
D45: Enter description | E45: Description should be displayed | F45: Pass
D46: Select a form type (External) | E46: Form type external radio button should be selected | F46: Pass
D47: Click on Create button | E47: Should display a successful message, "form created successfully.' | F47: Pass
...

Sheet CONTACTS
I2: Pass
I3: Fail
D6: ECMS Test Script
D8: Date : | F8: Tester Name & Sign:
F9: Version:
F10: Environment: | G10: Pre Production
D11: Number of Passed Test Scenarios: | E11: =COUNTIF(F18:F172,I2) -> 100 | F11: Doc Category: | G11: Internal
D12: Number of Failed Test Scenarios: | E12: =COUNTIF(F19:F172,I3) -> 1 | F12: % of Passed Test Scenarios: | G12: =(E11/E13)*100 -> 99.009901
D13: Number of Test Scenarios: | E13: =SUM(E11:E12) -> 101 | F13: % of Failed Test Scenarios: | G13: =(E12/E13)*100 -> 0.99009901
B16: Features | D16: Steps to Reproduce | E16: Expected results | F16: Pass/Fail | G16: Comments and Observations
B18: CONTACTS | D18: Create a Contacts
D19: Contact Form | F19: Pass
D20: Click on contact in the menu | E20: Should display contact page | F20: Pass
D21: Click on create contact | E21: Should display contact form page. | F21: Pass
D22: Enter First name | E22: FirstName entered should be accepted | F22: Pass
D23: Enter Last name | E23: LastName entered should be accepted | F23: Pass
D24: Enter email address | E24: The valid Email address should be accepted | F24: Pass
D25: Enter phone number | E25: The phone number should be accepted | F25: Pass
D26: Address 1 & Address 2 | E26: The address 1 & address 2 should be accepted | F26: Pass
D27: Select country | E27: The country should be selected and accepted | F27: Pass
D28: Select state | E28: The state should be selected and accepted
D29: Enter city | E29: The city should be accepted | F29: Pass
D30: Select life cycle stages | E30: The life cycle stage should be selected and accepted | F30: Pass
D31: Select Date of Birth | E31: The date of birth should be accepted
D32: Enter Linkedin link | E32: The Linkedin should be accepted | F32: Pass
D33: Enter Twitter link | E33: The twitter link should be accepted
D34: End Test
D36: Click on add field | E36: A display of multiple checkboxes (Prefix, Middle name, Website URL) should be displayed | F36: Pass
D37: Check on the prefix box & Enter Prefix | E37: The prefix field should be toggled on and the prefix entered should be accepted | F37: Pass
D38: Check the Middle name box & Enter Middle name | E38: The middle name field should be toggled on and the Middle name entered is accepted | F38: Pass
D39: Check the website URL | E39: The website URL field should be toggled on and the website URL entered should be accepted | F39: Pass
D40: Click on save button | E40: The contact should be saved successfully | F40: Pass
D41: Click on cancel button | E41: The contact form should be closed | F41: Pass
D42: End Test
D44: Update Contacts
D45: Click on contact in the menu | E45: Should display contact page | F45: Pass
D46: Click on The contact action button | E46: Should Display all the action options e.g. View and Update | F46: Pass
D47: Click on update | E47: Should display the contact update's page | F47: Pass
D48: Enter First name | E48: FirstName entered should be accepted | F48: Pass
D49: Enter Last name | E49: LastName entered should be accepted | F49: Pass
...

Sheet USER
I2: Pass
I3: Fail
D6: ECMS Test Script
D8: Date : | F8: Tester Name & Sign:
F9: Version:
F10: Environment: | G10: Pre Production
D11: Number of Passed Test Scenarios: | E11: =COUNTIF(F18:F229,I2) -> 96 | F11: Doc Category: | G11: Internal
D12: Number of Failed Test Scenarios: | E12: =COUNTIF(F18:F229,I3) -> 9 | F12: % of Passed Test Scenarios: | G12: =(E11/E13)*100 -> 91.428571
D13: Number of Test Scenarios: | E13: =SUM(E11:E12) -> 105 | F13: % of Failed Test Scenarios: | G13: =(E12/E13)*100 -> 8.5714286
B16: Features | D16: Steps to Reproduce | E16: Expected results | F16: Pass/Fail | G16: Comments and Observations
B18: USER | D18: Create User valid Credential
D19: From the Menu click on User | E19: A sub menu "roles, Department, user" should be displayed. | F19: Pass
D20: Click on User sub -menu | E20: Display User page | F20: Pass
D21: Click on Create button | E21: Display new user page | F21: Pass
D22: Enter FirstName | E22: Display First Name | F22: Pass
D23: Enter Last Name | E23: Display Last Name | F23: Pass
D24: Enter Email address | E24: Display Email address | F24: Pass
D25: Enter Phone number | E25: Display Phone number | F25: Pass
D26: Click and select role | E26: Display role | F26: Pass
D27: Click and select Department | E27: Display Department | F27: Pass
D28: Select Grade Level | E28: Display list of grade levels | F28: Pass
D29: Select Line Manager | E29: Display list of users | F29: Pass
D30: Upload Image | E30: Display image file in png, jpeg, | F30: Pass | G30: Update required
D31: Enter staff ID | E31: Display staff ID | F31: Pass
D32: Enter Job Title | E32: Display Job title | F32: Pass
D33: Enter Regions | E33: Display Region | F33: Pass
D34: Click on Create button | E34: Display a successful message, " successfully Created.'
D35: End test
D38: Create User invalid Credential
D39: From the Menu click on User | E39: A sub menu "roles, Department, user" should be displayed. | F39: Fail | G39: Update required
D40: Click on User sub -menu | E40: Display User page | F40: Fail | G40: Update required
D41: Click on Create button | E41: Display new user page | F41: Fail | G41: Update required
D42: Enter FirstName | E42: should not accept invalid First Name | F42: Fail | G42: Update required
D43: Enter Last Name | E43: should not accept invalid larst Name | F43: Fail | G43: Update required
D44: Enter Email address | E44: should not accept invalid email address | F44: Fail | G44: Update required
D45: Enter Phone number | E45: should not accept invalid phone number | F45: Fail
D46: Click and select role | E46: Display role | F46: Pass
D47: Click and select Department | E47: Display Department | F47: Pass
D48: Upload Image | E48: Display image file in png, jpeg, | F48: Pass | G48: Pass
D49: Enter staff ID | E49: Display staff ID | F49: Pass | G49: Pass
...
